Workbook

Sheet Uylar royxati
A1: ID | B1: Bino | C1: Pod'ezd | D1: Qavat | E1: Xonadon raqami | F1: Xona turi | G1: Maydon (m²) | H1: 1 m² narx | I1: Umumiy narx | J1: Boshlang'ich to'lov | K1: Qoldiq | L1: Status | M1: Mijoz F.I.Sh | N1: Manzil | O1: Pasport | P1: Kim tomonidan berilgan | Q1: Pasport berilgan sana | R1: Telefon 1 | S1: Telefon 2 | T1: Shartnoma sanasi | U1: Shartnoma № | V1: MapKey | W1: LockedBy | X1: LockTime | Y1: Deadline | Z1: Izoh
A2: 1 | B2: 1 | C2: 1 | D2: 1 | E2: 1 | F2: 2 хонали | G2: 48.15 | H2: 7700000 | I2: 370755000 | J2: =I2*Settings!$B$2 -> 74151000 | K2: =I2-J2 -> 296604000 | L2: Sotildi | M2: Nosirova Gulshanoy Fayzullayevna | R2: 881776670 | S2: 934229955 | T2: 46076 | U2: =TEXT(T2,"dd")&"/"&TEXT(E2,"00") -> dd/01 | V2: =C2&"-"&E2 -> 1-1
A3: 2 | B3: 1 | C3: 1 | D3: 1 | E3: 2 | F3: 1 хонали | G3: 28.52 | H3: {=INDEX(Settings!$B$3:$B$7, D3)} -> 7700000 | I3: =G3*H3 -> 219604000 | J3: =I3*Settings!$B$2 -> 43920800 | K3: =I3-J3 -> 175683200 | L3: Sotildi | M3: Samadov Obloqul | T3: 46071 | U3: =TEXT(T3,"dd")&"/"&TEXT(E3,"00") -> dd/02 | V3: =C3&"-"&E3 -> 1-2
A4: 3 | B4: 1 | C4: 1 | D4: 1 | E4: 3 | F4: 1 хонали | G4: 31.31 | H4: {=INDEX(Settings!$B$3:$B$7, D4)} -> 7700000 | I4: =G4*H4 -> 241087000 | J4: =I4*Settings!$B$2 -> 48217400 | K4: =I4-J4 -> 192869600 | L4: Sotildi | M4: Hayrullayev Nurbek Ruzi o'g'li | T4: 46066 | U4: =TEXT(T4,"dd")&"/"&TEXT(E4,"00") -> dd/03 | V4: =C4&"-"&E4 -> 1-3
A5: 4 | B5: 1 | C5: 1 | D5: 1 | E5: 4 | F5: 1 хонали | G5: 29.04 | H5: {=INDEX(Settings!$B$3:$B$7, D5)} -> 7700000 | I5: =G5*H5 -> 223608000 | J5: =I5*Settings!$B$2 -> 44721600 | K5: =I5-J5 -> 178886400 | L5: Sotildi | M5: Yarmatova Feruza Xushvaqtova | T5: 46078 | U5: =TEXT(T5,"dd")&"/"&TEXT(E5,"00") -> dd/04 | V5: =C5&"-"&E5 -> 1-4
A6: 5 | B6: 1 | C6: 1 | D6: 2 | E6: 5 | F6: 2 хонали | G6: 48.15 | H6: {=INDEX(Settings!$B$3:$B$7, D6)} -> 7800000 | I6: =G6*H6 -> 375570000 | J6: =I6*Settings!$B$2 -> 75114000 | K6: =I6-J6 -> 300456000 | L6: Sotildi | M6: Xoliqo Umidjon Boltayevich | R6: 332662514 | T6: 45957 | U6: =TEXT(T6,"dd")&"/"&TEXT(E6,"00") -> dd/05 | V6: =C6&"-"&E6 -> 1-5
A7: 6 | B7: 1 | C7: 1 | D7: 2 | E7: 6 | F7: 1 хонали | G7: 28.52 | H7: {=INDEX(Settings!$B$3:$B$7, D7)} -> 7800000 | I7: =G7*H7 -> 222456000 | J7: =I7*Settings!$B$2 -> 44491200 | K7: =I7-J7 -> 177964800 | L7: Sotildi | M7: Zokirova Nilufar Zokir qizi | R7: 973197588 | T7: 46015 | U7: =TEXT(T7,"dd")&"/"&TEXT(E7,"00") -> dd/06 | V7: =C7&"-"&E7 -> 1-6
A8: 7 | B8: 1 | C8: 1 | D8: 2 | E8: 7 | F8: 1 хонали | G8: 31.31 | H8: {=INDEX(Settings!$B$3:$B$7, D8)} -> 7800000 | I8: =G8*H8 -> 244218000 | J8: =I8*Settings!$B$2 -> 48843600 | K8: =I8-J8 -> 195374400 | L8: Sotildi | M8: Xomidov Xurshid Fozilovich | R8: 500472781 | T8: 46063 | U8: =TEXT(T8,"dd")&"/"&TEXT(E8,"00") -> dd/07 | V8: =C8&"-"&E8 -> 1-7
A9: 8 | B9: 1 | C9: 1 | D9: 2 | E9: 8 | F9: 1 хонали | G9: 29.04 | H9: {=INDEX(Settings!$B$3:$B$7, D9)} -> 7800000 | I9: =G9*H9 -> 226512000 | J9: =I9*Settings!$B$2 -> 45302400 | K9: =I9-J9 -> 181209600 | L9: Sotildi | M9: Xomidova Feruza Fozil qizi | R9: 973831989 | T9: 30.01.2026 | U9: =TEXT(T9,"dd")&"/"&TEXT(E9,"00") -> dd/08 | V9: =C9&"-"&E9 -> 1-8 | W9: Rahmatullayeva Sevinch
A10: 9 | B10: 1 | C10: 1 | D10: 3 | E10: 9 | F10: 2 хонали | G10: 48.15 | H10: {=INDEX(Settings!$B$3:$B$7, D10)} -> 7300000 | I10: =G10*H10 -> 351495000 | J10: =I10*Settings!$B$2 -> 70299000 | K10: =I10-J10 -> 281196000 | L10: Sotildi | M10: Ro'yeva Zulayxo Furqat qizi | T10: 45953 | U10: =TEXT(T10,"dd")&"/"&TEXT(E10,"00") -> dd/09 | V10: =C10&"-"&E10 -> 1-9
A11: 10 | B11: 1 | C11: 1 | D11: 3 | E11: 10 | F11: 1 хонали | G11: 28.52 | H11: {=INDEX(Settings!$B$3:$B$7, D11)} -> 7300000 | I11: =G11*H11 -> 208196000 | J11: =I11*Settings!$B$2 -> 41639200 | K11: =I11-J11 -> 166556800 | L11: Sotildi | M11: Ortiqova Zulfizar Sodiq qizi | R11: 918108592 | S11: 918162314 | T11: 45947 | U11: =TEXT(T11,"dd")&"/"&TEXT(E11,"00") -> dd/10 | V11: =C11&"-"&E11 -> 1-10
A12: 11 | B12: 1 | C12: 1 | D12: 3 | E12: 11 | F12: 1 хонали | G12: 31.31 | H12: {=INDEX(Settings!$B$3:$B$7, D12)} -> 7300000 | I12: =G12*H12 -> 228563000 | J12: =I12*Settings!$B$2 -> 45712600 | K12: =I12-J12 -> 182850400 | L12: Sotildi | M12: Boxodirov Xasan Otabek o'g'li | R12: 904433033 | S12: 942727273 | T12: 46003 | U12: =TEXT(T12,"dd")&"/"&TEXT(E12,"00") -> dd/11 | V12: =C12&"-"&E12 -> 1-11 | W12: Amirova Gavhar
A13: 12 | B13: 1 | C13: 1 | D13: 3 | E13: 12 | F13: 1 хонали | G13: 29.04 | H13: {=INDEX(Settings!$B$3:$B$7, D13)} -> 7300000 | I13: =G13*H13 -> 211992000 | J13: =I13*Settings!$B$2 -> 42398400 | K13: =I13-J13 -> 169593600 | L13: Sotildi | M13: Azratqulova Dilobar Samad qizi | R13: 882817393 | S13: 882866993 | T13: 46017 | U13: =TEXT(T13,"dd")&"/"&TEXT(E13,"00") -> dd/12 | V13: =C13&"-"&E13 -> 1-12
A14: 13 | B14: 1 | C14: 1 | D14: 4 | E14: 13 | F14: 2 хонали | G14: 48.15 | H14: {=INDEX(Settings!$B$3:$B$7, D14)} -> 7000000 | I14: =G14*H14 -> 337050000 | J14: =I14*Settings!$B$2 -> 67410000 | K14: =I14-J14 -> 269640000 | L14: Sotildi | M14: Boynazarova Guzalxon Bektosh qizi | R14: 903299092 | S14: 916345260 | T14: 45943 | U14: =TEXT(T14,"dd")&"/"&TEXT(E14,"00") -> dd/13 | V14: =C14&"-"&E14 -> 1-13
A15: 14 | B15: 1 | C15: 1 | D15: 4 | E15: 14 | F15: 1 хонали | G15: 28.52 | H15: {=INDEX(Settings!$B$3:$B$7, D15)} -> 7000000 | I15: =G15*H15 -> 199640000 | J15: =I15*Settings!$B$2 -> 39928000 | K15: =I15-J15 -> 159712000 | L15: Sotildi | M15: Nasrullayeva Maftuna Farxod qizi | R15: 973810204 | T15: 45943 | U15: =TEXT(T15,"dd")&"/"&TEXT(E15,"00") -> dd/14 | V15: =C15&"-"&E15 -> 1-14
A16: 15 | B16: 1 | C16: 1 | D16: 4 | E16: 15 | F16: 1 хонали | G16: 31.31 | H16: {=INDEX(Settings!$B$3:$B$7, D16)} -> 7000000 | I16: =G16*H16 -> 219170000 | J16: =I16*Settings!$B$2 -> 43834000 | K16: =I16-J16 -> 175336000 | L16: Sotildi | M16: To'ychiyeva Matluba Ibodulla qizi | R16: 916374850 | T16: 45957 | U16: =TEXT(T16,"dd")&"/"&TEXT(E16,"00") -> dd/15 | V16: =C16&"-"&E16 -> 1-15
A17: 16 | B17: 1 | C17: 1 | D17: 4 | E17: 16 | F17: 1 хонали | G17: 29.04 | H17: {=INDEX(Settings!$B$3:$B$7, D17)} -> 7000000 | I17: =G17*H17 -> 203280000 | J17: =I17*Settings!$B$2 -> 40656000 | K17: =I17-J17 -> 162624000 | L17: Sotildi | M17: Neymatov Shuhrat Ilhom o'g'li | R17: 880347722 | T17: 45974 | U17: =TEXT(T17,"dd")&"/"&TEXT(E17,"00") -> dd/16 | V17: =C17&"-"&E17 -> 1-16
A18: 17 | B18: 1 | C18: 1 | D18: 5 | E18: 17 | F18: 2 хонали | G18: 48.15 | H18: 6700000 | I18: 322605000 | J18: 64521000 | K18: 258084000 | L18: Sotildi | M18: Gadoyev Muxlis Kucharovich | R18: 770483237 | T18: 45954 | U18: 30/17 | V18: 1-17 | W18: Sunnatillo Saidjonov | Z18: 1
A19: 18 | B19: 1 | C19: 1 | D19: 5 | E19: 18 | F19: 1 хонали | G19: 28.52 | H19: {=INDEX(Settings!$B$3:$B$7, D19)} -> 6700000 | I19: =G19*H19 -> 191084000 | J19: =I19*Settings!$B$2 -> 38216800 | K19: =I19-J19 -> 152867200 | L19: Sotildi | M19: Hazratova Iroda Hamroqulovna | R19: 880820690 | T19: 45952 | U19: =TEXT(T19,"dd")&"/"&TEXT(E19,"00") -> dd/18 | V19: =C19&"-"&E19 -> 1-18
A20: 19 | B20: 1 | C20: 1 | D20: 5 | E20: 19 | F20: 1 хонали | G20: 31.31 | H20: {=INDEX(Settings!$B$3:$B$7, D20)} -> 6700000 | I20: =G20*H20 -> 209777000 | J20: =I20*Settings!$B$2 -> 41955400 | K20: =I20-J20 -> 167821600 | L20: Sotildi | M20: Zoidova Aziza G'ulom qizi | R20: 504073155 | T20: 45994 | U20: =TEXT(T20,"dd")&"/"&TEXT(E20,"00") -> dd/19 | V20: =C20&"-"&E20 -> 1-19
A21: 20 | B21: 1 | C21: 1 | D21: 5 | E21: 20 | F21: 1 хонали | G21: 29.04 | H21: {=INDEX(Settings!$B$3:$B$7, D21)} -> 6700000 | I21: =G21*H21 -> 194568000 | J21: =I21*Settings!$B$2 -> 38913600 | K21: =I21-J21 -> 155654400 | L21: Sotildi | M21: Muhammadiyeva Charos Keldiyorovna | R21: 882800012 | T21: 45951 | U21: =TEXT(T21,"dd")&"/"&TEXT(E21,"00") -> dd/20 | V21: =C21&"-"&E21 -> 1-20
A22: 21 | B22: 1 | C22: 2 | D22: 1 | E22: 21 | F22: 2 хонали | G22: 48.15 | H22: {=INDEX(Settings!$B$3:$B$7, D22)} -> 7700000 | I22: =G22*H22 -> 370755000 | J22: =I22*Settings!$B$2 -> 74151000 | K22: =I22-J22 -> 296604000 | L22: Sotildi | M22: Urinov Sardor Komil o'g'li | R22: 943361708 | T22: 46048 | U22: =TEXT(T22,"dd")&"/"&TEXT(E22,"00") -> dd/21 | V22: =C22&"-"&E22 -> 2-21
A23: 22 | B23: 1 | C23: 2 | D23: 1 | E23: 22 | F23: 1 хонали | G23: 28.52 | H23: {=INDEX(Settings!$B$3:$B$7, D23)} -> 7700000 | I23: =G23*H23 -> 219604000 | J23: =I23*Settings!$B$2 -> 43920800 | K23: =I23-J23 -> 175683200 | L23: Sotildi | M23: Ruzimurodov Jamshid Quychi o'g'li | R23: 886182000 | T23: 46048 | U23: =TEXT(T23,"dd")&"/"&TEXT(E23,"00") -> dd/22 | V23: =C23&"-"&E23 -> 2-22 | W23: Amirova Gavhar
A24: 23 | B24: 1 | C24: 2 | D24: 1 | E24: 23 | F24: 1 хонали | G24: 31.31 | H24: {=INDEX(Settings!$B$3:$B$7, D24)} -> 7700000 | I24: =G24*H24 -> 241087000 | J24: =I24*Settings!$B$2 -> 48217400 | K24: =I24-J24 -> 192869600 | L24: Sotildi | M24: Quyliyev Shahzod Baxriddin o'g'li | R24: 9975896061 | T24: 46048 | U24: =TEXT(T24,"dd")&"/"&TEXT(E24,"00") -> dd/23 | V24: =C24&"-"&E24 -> 2-23 | W24: Amirova Gavhar
A25: 24 | B25: 1 | C25: 2 | D25: 1 | E25: 24 | F25: 1 хонали | G25: 29.04 | H25: {=INDEX(Settings!$B$3:$B$7, D25)} -> 7700000 | I25: =G25*H25 -> 223608000 | J25: =I25*Settings!$B$2 -> 44721600 | K25: =I25-J25 -> 178886400 | L25: Sotildi | M25: Eshnazarov Eldor Eshnazar o'g'li | R25: 889242026 | T25: 46048 | U25: =TEXT(T25,"dd")&"/"&TEXT(E25,"00") -> dd/24 | V25: =C25&"-"&E25 -> 2-24 | W25: Amirova Gavhar
A26: 25 | B26: 1 | C26: 2 | D26: 2 | E26: 25 | F26: 2 хонали | G26: 48.15 | H26: {=INDEX(Settings!$B$3:$B$7, D26)} -> 7800000 | I26: =G26*H26 -> 375570000 | J26: =I26*Settings!$B$2 -> 75114000 | K26: =I26-J26 -> 300456000 | L26: Sotildi | M26: Artiqova Lobaroy Komolovna | R26: 974777786 | S26: 990648728 | T26: 46008 | U26: =TEXT(T26,"dd")&"/"&TEXT(E26,"00") -> dd/25 | V26: =C26&"-"&E26 -> 2-25 | W26: Rahmatullayeva Sevinch
A27: 26 | B27: 1 | C27: 2 | D27: 2 | E27: 26 | F27: 1 хонали | G27: 28.52 | H27: {=INDEX(Settings!$B$3:$B$7, D27)} -> 7800000 | I27: =G27*H27 -> 222456000 | J27: =I27*Settings!$B$2 -> 44491200 | K27: =I27-J27 -> 177964800 | L27: Sotildi | M27: Haqberdiyeva Komila Xudoyberdiyevna | R27: 906661514 | S27: 900140384 | T27: 45924 | U27: =TEXT(T27,"dd")&"/"&TEXT(E27,"00") -> dd/26 | V27: =C27&"-"&E27 -> 2-26 | W27: Saidjonov Sunnatillo
A28: 27 | B28: 1 | C28: 2 | D28: 2 | E28: 27 | F28: 1 хонали | G28: 31.31 | H28: {=INDEX(Settings!$B$3:$B$7, D28)} -> 7800000 | I28: =G28*H28 -> 244218000 | J28: =I28*Settings!$B$2 -> 48843600 | K28: =I28-J28 -> 195374400 | L28: Sotildi | M28: Salomov Akmal Xoliqovich | R28: 996294189 | T28: 46034 | U28: =TEXT(T28,"dd")&"/"&TEXT(E28,"00") -> dd/27 | V28: =C28&"-"&E28 -> 2-27 | W28: Saidjonov Sunnatillo
A29: 28 | B29: 1 | C29: 2 | D29: 2 | E29: 28 | F29: 1 хонали | G29: 29.04 | H29: {=INDEX(Settings!$B$3:$B$7, D29)} -> 7800000 | I29: =G29*H29 -> 226512000 | J29: =I29*Settings!$B$2 -> 45302400 | K29: =I29-J29 -> 181209600 | L29: Sotildi | M29: Aliyeva Navruza Ziyodullayevna | R29: 996241899 | T29: 46034 | U29: =TEXT(T29,"dd")&"/"&TEXT(E29,"00") -> dd/28 | V29: =C29&"-"&E29 -> 2-28 | W29: Rahmatullayeva Sevinch
A30: 29 | B30: 1 | C30: 2 | D30: 3 | E30: 29 | F30: 2 хонали | G30: 48.15 | H30: {=INDEX(Settings!$B$3:$B$7, D30)} -> 7300000 | I30: =G30*H30 -> 351495000 | J30: =I30*Settings!$B$2 -> 70299000 | K30: =I30-J30 -> 281196000 | L30: Sotildi | M30: Saidjonova Yulduz Zarif qizi | R30: 888017977 | S30: 9971717977 | T30: 45924 | U30: =TEXT(T30,"dd")&"/"&TEXT(E30,"00") -> dd/29 | V30: =C30&"-"&E30 -> 2-29 | W30: Saidjonov Sunnatillo
A31: 30 | B31: 1 | C31: 2 | D31: 3 | E31: 30 | F31: 1 хонали | G31: 28.52 | H31: {=INDEX(Settings!$B$3:$B$7, D31)} -> 7300000 | I31: =G31*H31 -> 208196000 | J31: =I31*Settings!$B$2 -> 41639200 | K31: =I31-J31 -> 166556800 | L31: Sotildi | M31: Sadullayev Og'abek Otabek o'g'li | R31: 992999001 | S31: 997239001 | T31: 46000 | U31: =TEXT(T31,"dd")&"/"&TEXT(E31,"00") -> dd/30 | V31: =C31&"-"&E31 -> 2-30
A32: 31 | B32: 1 | C32: 2 | D32: 3 | E32: 31 | F32: 1 хонали | G32: 31.31 | H32: {=INDEX(Settings!$B$3:$B$7, D32)} -> 7300000 | I32: =G32*H32 -> 228563000 | J32: =I32*Settings!$B$2 -> 45712600 | K32: =I32-J32 -> 182850400 | L32: Sotildi | M32: Qulmatova Mu'tabar Jurayevna | R32: 976720483 | T32: 45929 | U32: =TEXT(T32,"dd")&"/"&TEXT(E32,"00") -> dd/31 | V32: =C32&"-"&E32 -> 2-31
A33: 32 | B33: 1 | C33: 2 | D33: 3 | E33: 32 | F33: 1 хонали | G33: 29.04 | H33: {=INDEX(Settings!$B$3:$B$7, D33)} -> 7300000 | I33: =G33*H33 -> 211992000 | J33: =I33*Settings!$B$2 -> 42398400 | K33: =I33-J33 -> 169593600 | L33: Sotildi | M33: Nabiyeva Shaxnoza Burxonovna | R33: 970831948 | T33: 46031 | U33: =TEXT(T33,"dd")&"/"&TEXT(E33,"00") -> dd/32 | V33: =C33&"-"&E33 -> 2-32
A34: 33 | B34: 1 | C34: 2 | D34: 4 | E34: 33 | F34: 2 хонали | G34: 48.15 | H34: {=INDEX(Settings!$B$3:$B$7, D34)} -> 7000000 | I34: =G34*H34 -> 337050000 | J34: =I34*Settings!$B$2 -> 67410000 | K34: =I34-J34 -> 269640000 | L34: Sotildi | M34: Ashurova Bobur Baxodir o'g'li | R34: 977233396 | T34: 45944 | U34: =TEXT(T34,"dd")&"/"&TEXT(E34,"00") -> dd/33 | V34: =C34&"-"&E34 -> 2-33
A35: 34 | B35: 1 | C35: 2 | D35: 4 | E35: 34 | F35: 1 хонали | G35: 28.52 | H35: {=INDEX(Settings!$B$3:$B$7, D35)} -> 7000000 | I35: =G35*H35 -> 199640000 | J35: =I35*Settings!$B$2 -> 39928000 | K35: =I35-J35 -> 159712000 | L35: Sotildi | M35: Turayeva Shaxlo Amirovna | R35: 906712577 | S35: 908821527 | T35: 45992 | U35: =TEXT(T35,"dd")&"/"&TEXT(E35,"00") -> dd/34 | V35: =C35&"-"&E35 -> 2-34
A36: 35 | B36: 1 | C36: 2 | D36: 4 | E36: 35 | F36: 1 хонали | G36: 31.31 | H36: {=INDEX(Settings!$B$3:$B$7, D36)} -> 7000000 | I36: =G36*H36 -> 219170000 | J36: =I36*Settings!$B$2 -> 43834000 | K36: =I36-J36 -> 175336000 | L36: Sotildi | M36: Qurbonova O'g'iloy Baxriddin qizi | R36: 970662728 | T36: 45926 | U36: =TEXT(T36,"dd")&"/"&TEXT(E36,"00") -> dd/35 | V36: =C36&"-"&E36 -> 2-35
A37: 36 | B37: 1 | C37: 2 | D37: 4 | E37: 36 | F37: 1 хонали | G37: 29.04 | H37: {=INDEX(Settings!$B$3:$B$7, D37)} -> 7000000 | I37: =G37*H37 -> 203280000 | J37: =I37*Settings!$B$2 -> 40656000 | K37: =I37-J37 -> 162624000 | L37: Sotildi | M37: Radjabova Zulayxo Narzikulovna | R37: 976317730 | S37: 883836077 | T37: 45966 | U37: =TEXT(T37,"dd")&"/"&TEXT(E37,"00") -> dd/36 | V37: =C37&"-"&E37 -> 2-36 | W37: Saidjonov Sunnatillo
A38: 37 | B38: 1 | C38: 2 | D38: 5 | E38: 37 | F38: 2 хонали | G38: 48.15 | H38: {=INDEX(Settings!$B$3:$B$7, D38)} -> 6700000 | I38: =G38*H38 -> 322605000 | J38: =I38*Settings!$B$2 -> 64521000 | K38: =I38-J38 -> 258084000 | L38: Sotildi | M38: Usmonov Sohib G'ayrat o'g'li | R38: 995076514 | S38: 908999109 | T38: 45950 | U38: =TEXT(T38,"dd")&"/"&TEXT(E38,"00") -> dd/37 | V38: =C38&"-"&E38 -> 2-37
A39: 38 | B39: 1 | C39: 2 | D39: 5 | E39: 38 | F39: 1 хонали | G39: 28.52 | H39: {=INDEX(Settings!$B$3:$B$7, D39)} -> 6700000 | I39: =G39*H39 -> 191084000 | J39: =I39*Settings!$B$2 -> 38216800 | K39: =I39-J39 -> 152867200 | L39: Sotildi | M39: Kamolov Lazizbek Ravshan ugl | R39: 914564852 | S39: 904280318 | T39: 45989 | U39: =TEXT(T39,"dd")&"/"&TEXT(E39,"00") -> dd/38 | V39: =C39&"-"&E39 -> 2-38
A40: 39 | B40: 1 | C40: 2 | D40: 5 | E40: 39 | F40: 1 хонали | G40: 31.31 | H40: {=INDEX(Settings!$B$3:$B$7, D40)} -> 6700000 | I40: =G40*H40 -> 209777000 | J40: =I40*Settings!$B$2 -> 41955400 | K40: =I40-J40 -> 167821600 | L40: Sotildi | M40: Mingboeva Dilrabo Abdurasul Qizi | R40: 873119555 | S40: 979509597 | T40: 45978 | U40: =TEXT(T40,"dd")&"/"&TEXT(E40,"00") -> dd/39 | V40: =C40&"-"&E40 -> 2-39
...

Sheet Users
A1: Login | B1: Parol | C1: Rol | D1: To'liq F.I.Sh | E1: Telegram ID
A2: Saidjonov_Sunnatillo | B2: S19991226 | C2: Admin | D2: Saidjonov Sunnatillo
A3: Abdivoitov_Mansur | B3: 770147747 | C3: Sotuv Menejeri | D3: Abdivoitov Mansur | E3: 8136738818
A4: Amirova_Gavhar | B4: 770167747 | C4: Sotuv Menejeri | D4: Amirova Gavhar | E4: 5701866738
A5: Amirova_Farinoz | B5: F0111 | C5: Mobilogrof & Aloqa operator | D5: Amirova Farinoz
A6: Rahmatullayeva_Sevinch | B6: 772667747 | C6: Sotuv Menejeri | D6: Amirova Farinoz | E6: 8429865179
A7: Alisher_Samadov | B7: A3538 | C7: Derektor | D7: Samadov Alisher

Sheet Settings
A1: FAYZLI XONADONLAR - 2-BINO TIZIMI
A2: Boshlang'ich to'lov ulushi | B2: 0.2
A3: 1-qavat narxi (so'm / m²) | B3: 7700000
A4: 2-qavat narxi (so'm / m²) | B4: 7800000
A5: 3-qavat narxi (so'm / m²) | B5: 7300000
A6: 4-qavat narxi (so'm / m²) | B6: 7000000
A7: 5-qavat narxi (so'm / m²) | B7: 6700000
A8: Sotuvchi tashkilot | B8: KITOB FAYZ QURILISH MCHJ
A9: Direktor | B9: Samadov Alisher Qiyomiddin o‘g‘li
A10: Obyekt manzili | B10: Kitob tumani Guliston MFY Guliston ko‘chasi
